DEBUG    tests.moduletest.conftest:conftest.py:25 Loaded .env from C:\Users\E017093\gitRepos\PolarionMock\.env
INFO     tests.session:conftest.py:231 ================================================================================
INFO     tests.session:conftest.py:232 Test Session Started: 20250806_090529
INFO     tests.session:conftest.py:233 Environment: production
INFO     tests.session:conftest.py:234 ================================================================================
DEBUG    tests.session:conftest.py:151 Test environment: production
DEBUG    tests.session:conftest.py:152 Base URL: N/A
INFO     polarion_api.client:client.py:60 Initialized Polarion client for https://polarion-d.claas.local
INFO     polarion_api.documents:documents.py:398 Starting document and space discovery for project: Python
DEBUG    polarion_api.documents:documents.py:415 Fetching documents page 1 for project Python
DEBUG    polarion_api.client:client.py:107 GET https://polarion-d.claas.local/polarion/rest/projects/Python/documents
DEBUG    urllib3.connectionpool:connectionpool.py:1049 Starting new HTTPS connection (1): polarion-d.claas.local:443
DEBUG    urllib3.util.retry:retry.py:521 Incremented Retry for (url='/polarion/rest/projects/Python/documents?page%5Bsize%5D=100&page%5Bnumber%5D=1&fields%5Bdocuments%5D=id%2Ctitle%2Ctype%2CmoduleURI%2CspaceId'): Retry(total=2, connect=None, read=None, redirect=None, status=None)
WARNING  urllib3.connectionpool:connectionpool.py:868 Retrying (Retry(total=2, connect=None, read=None, redirect=None, status=None)) after connection broken by 'NameResolutionError("<urllib3.connection.HTTPSConnection object at 0x000002029555BA10>: Failed to resolve 'polarion-d.claas.local' ([Errno 11001] getaddrinfo failed)")': /polarion/rest/projects/Python/documents?page%5Bsize%5D=100&page%5Bnumber%5D=1&fields%5Bdocuments%5D=id%2Ctitle%2Ctype%2CmoduleURI%2CspaceId
DEBUG    urllib3.connectionpool:connectionpool.py:1049 Starting new HTTPS connection (2): polarion-d.claas.local:443
DEBUG    urllib3.util.retry:retry.py:521 Incremented Retry for (url='/polarion/rest/projects/Python/documents?page%5Bsize%5D=100&page%5Bnumber%5D=1&fields%5Bdocuments%5D=id%2Ctitle%2Ctype%2CmoduleURI%2CspaceId'): Retry(total=1, connect=None, read=None, redirect=None, status=None)
WARNING  urllib3.connectionpool:connectionpool.py:868 Retrying (Retry(total=1, connect=None, read=None, redirect=None, status=None)) after connection broken by 'NameResolutionError("<urllib3.connection.HTTPSConnection object at 0x000002029555EFD0>: Failed to resolve 'polarion-d.claas.local' ([Errno 11001] getaddrinfo failed)")': /polarion/rest/projects/Python/documents?page%5Bsize%5D=100&page%5Bnumber%5D=1&fields%5Bdocuments%5D=id%2Ctitle%2Ctype%2CmoduleURI%2CspaceId
DEBUG    urllib3.connectionpool:connectionpool.py:1049 Starting new HTTPS connection (3): polarion-d.claas.local:443
DEBUG    urllib3.util.retry:retry.py:521 Incremented Retry for (url='/polarion/rest/projects/Python/documents?page%5Bsize%5D=100&page%5Bnumber%5D=1&fields%5Bdocuments%5D=id%2Ctitle%2Ctype%2CmoduleURI%2CspaceId'): Retry(total=0, connect=None, read=None, redirect=None, status=None)
WARNING  urllib3.connectionpool:connectionpool.py:868 Retrying (Retry(total=0, connect=None, read=None, redirect=None, status=None)) after connection broken by 'NameResolutionError("<urllib3.connection.HTTPSConnection object at 0x000002029555F250>: Failed to resolve 'polarion-d.claas.local' ([Errno 11001] getaddrinfo failed)")': /polarion/rest/projects/Python/documents?page%5Bsize%5D=100&page%5Bnumber%5D=1&fields%5Bdocuments%5D=id%2Ctitle%2Ctype%2CmoduleURI%2CspaceId
DEBUG    urllib3.connectionpool:connectionpool.py:1049 Starting new HTTPS connection (4): polarion-d.claas.local:443
ERROR    polarion_api.documents:documents.py:485 Error during document discovery: Failed to connect to https://polarion-d.claas.local/polarion/rest/projects/Python/documents: HTTPSConnectionPool(host='polarion-d.claas.local', port=443): Max retries exceeded with url: /polarion/rest/projects/Python/documents?page%5Bsize%5D=100&page%5Bnumber%5D=1&fields%5Bdocuments%5D=id%2Ctitle%2Ctype%2CmoduleURI%2CspaceId (Caused by NameResolutionError("<urllib3.connection.HTTPSConnection object at 0x000002029555F4D0>: Failed to resolve 'polarion-d.claas.local' ([Errno 11001] getaddrinfo failed)"))
INFO     polarion_api.documents:documents.py:513 Using fallback space discovery method
DEBUG    polarion_api.client:client.py:107 GET https://polarion-d.claas.local/polarion/rest/projects/Python/spaces/_default/documents
DEBUG    urllib3.connectionpool:connectionpool.py:1049 Starting new HTTPS connection (5): polarion-d.claas.local:443
DEBUG    urllib3.util.retry:retry.py:521 Incremented Retry for (url='/polarion/rest/projects/Python/spaces/_default/documents?page%5Bsize%5D=10&fields%5Bdocuments%5D=id%2Ctitle'): Retry(total=2, connect=None, read=None, redirect=None, status=None)
WARNING  urllib3.connectionpool:connectionpool.py:868 Retrying (Retry(total=2, connect=None, read=None, redirect=None, status=None)) after connection broken by 'NameResolutionError("<urllib3.connection.HTTPSConnection object at 0x000002029555FB10>: Failed to resolve 'polarion-d.claas.local' ([Errno 11001] getaddrinfo failed)")': /polarion/rest/projects/Python/spaces/_default/documents?page%5Bsize%5D=10&fields%5Bdocuments%5D=id%2Ctitle
DEBUG    urllib3.connectionpool:connectionpool.py:1049 Starting new HTTPS connection (6): polarion-d.claas.local:443
DEBUG    urllib3.util.retry:retry.py:521 Incremented Retry for (url='/polarion/rest/projects/Python/spaces/_default/documents?page%5Bsize%5D=10&fields%5Bdocuments%5D=id%2Ctitle'): Retry(total=1, connect=None, read=None, redirect=None, status=None)
WARNING  urllib3.connectionpool:connectionpool.py:868 Retrying (Retry(total=1, connect=None, read=None, redirect=None, status=None)) after connection broken by 'NameResolutionError("<urllib3.connection.HTTPSConnection object at 0x000002029555FD90>: Failed to resolve 'polarion-d.claas.local' ([Errno 11001] getaddrinfo failed)")': /polarion/rest/projects/Python/spaces/_default/documents?page%5Bsize%5D=10&fields%5Bdocuments%5D=id%2Ctitle
DEBUG    urllib3.connectionpool:connectionpool.py:1049 Starting new HTTPS connection (7): polarion-d.claas.local:443
DEBUG    urllib3.util.retry:retry.py:521 Incremented Retry for (url='/polarion/rest/projects/Python/spaces/_default/documents?page%5Bsize%5D=10&fields%5Bdocuments%5D=id%2Ctitle'): Retry(total=0, connect=None, read=None, redirect=None, status=None)
WARNING  urllib3.connectionpool:connectionpool.py:868 Retrying (Retry(total=0, connect=None, read=None, redirect=None, status=None)) after connection broken by 'NameResolutionError("<urllib3.connection.HTTPSConnection object at 0x0000020296878050>: Failed to resolve 'polarion-d.claas.local' ([Errno 11001] getaddrinfo failed)")': /polarion/rest/projects/Python/spaces/_default/documents?page%5Bsize%5D=10&fields%5Bdocuments%5D=id%2Ctitle
DEBUG    urllib3.connectionpool:connectionpool.py:1049 Starting new HTTPS connection (8): polarion-d.claas.local:443
DEBUG    polarion_api.documents:documents.py:555 Space '_default' not accessible: Failed to connect to https://polarion-d.claas.local/polarion/rest/projects/Python/spaces/_default/documents: HTTPSConnectionPool(host='polarion-d.claas.local', port=443): Max retries exceeded with url: /polarion/rest/projects/Python/spaces/_default/documents?page%5Bsize%5D=10&fields%5Bdocuments%5D=id%2Ctitle (Caused by NameResolutionError("<urllib3.connection.HTTPSConnection object at 0x00000202968782D0>: Failed to resolve 'polarion-d.claas.local' ([Errno 11001] getaddrinfo failed)"))
DEBUG    polarion_api.client:client.py:107 GET https://polarion-d.claas.local/polarion/rest/projects/Python/spaces/Default/documents
DEBUG    urllib3.connectionpool:connectionpool.py:1049 Starting new HTTPS connection (9): polarion-d.claas.local:443
DEBUG    urllib3.util.retry:retry.py:521 Incremented Retry for (url='/polarion/rest/projects/Python/spaces/Default/documents?page%5Bsize%5D=10&fields%5Bdocuments%5D=id%2Ctitle'): Retry(total=2, connect=None, read=None, redirect=None, status=None)
WARNING  urllib3.connectionpool:connectionpool.py:868 Retrying (Retry(total=2, connect=None, read=None, redirect=None, status=None)) after connection broken by 'NameResolutionError("<urllib3.connection.HTTPSConnection object at 0x0000020296878910>: Failed to resolve 'polarion-d.claas.local' ([Errno 11001] getaddrinfo failed)")': /polarion/rest/projects/Python/spaces/Default/documents?page%5Bsize%5D=10&fields%5Bdocuments%5D=id%2Ctitle
DEBUG    urllib3.connectionpool:connectionpool.py:1049 Starting new HTTPS connection (10): polarion-d.claas.local:443
DEBUG    urllib3.util.retry:retry.py:521 Incremented Retry for (url='/polarion/rest/projects/Python/spaces/Default/documents?page%5Bsize%5D=10&fields%5Bdocuments%5D=id%2Ctitle'): Retry(total=1, connect=None, read=None, redirect=None, status=None)
WARNING  urllib3.connectionpool:connectionpool.py:868 Retrying (Retry(total=1, connect=None, read=None, redirect=None, status=None)) after connection broken by 'NameResolutionError("<urllib3.connection.HTTPSConnection object at 0x0000020296878B90>: Failed to resolve 'polarion-d.claas.local' ([Errno 11001] getaddrinfo failed)")': /polarion/rest/projects/Python/spaces/Default/documents?page%5Bsize%5D=10&fields%5Bdocuments%5D=id%2Ctitle
DEBUG    urllib3.connectionpool:connectionpool.py:1049 Starting new HTTPS connection (11): polarion-d.claas.local:443
DEBUG    urllib3.util.retry:retry.py:521 Incremented Retry for (url='/polarion/rest/projects/Python/spaces/Default/documents?page%5Bsize%5D=10&fields%5Bdocuments%5D=id%2Ctitle'): Retry(total=0, connect=None, read=None, redirect=None, status=None)
WARNING  urllib3.connectionpool:connectionpool.py:868 Retrying (Retry(total=0, connect=None, read=None, redirect=None, status=None)) after connection broken by 'NameResolutionError("<urllib3.connection.HTTPSConnection object at 0x0000020296879090>: Failed to resolve 'polarion-d.claas.local' ([Errno 11001] getaddrinfo failed)")': /polarion/rest/projects/Python/spaces/Default/documents?page%5Bsize%5D=10&fields%5Bdocuments%5D=id%2Ctitle
DEBUG    urllib3.connectionpool:connectionpool.py:1049 Starting new HTTPS connection (12): polarion-d.claas.local:443
DEBUG    polarion_api.documents:documents.py:555 Space 'Default' not accessible: Failed to connect to https://polarion-d.claas.local/polarion/rest/projects/Python/spaces/Default/documents: HTTPSConnectionPool(host='polarion-d.claas.local', port=443): Max retries exceeded with url: /polarion/rest/projects/Python/spaces/Default/documents?page%5Bsize%5D=10&fields%5Bdocuments%5D=id%2Ctitle (Caused by NameResolutionError("<urllib3.connection.HTTPSConnection object at 0x0000020296879310>: Failed to resolve 'polarion-d.claas.local' ([Errno 11001] getaddrinfo failed)"))
DEBUG    polarion_api.client:client.py:107 GET https://polarion-d.claas.local/polarion/rest/projects/Python/spaces/default/documents
DEBUG    urllib3.connectionpool:connectionpool.py:1049 Starting new HTTPS connection (13): polarion-d.claas.local:443
DEBUG    urllib3.util.retry:retry.py:521 Incremented Retry for (url='/polarion/rest/projects/Python/spaces/default/documents?page%5Bsize%5D=10&fields%5Bdocuments%5D=id%2Ctitle'): Retry(total=2, connect=None, read=None, redirect=None, status=None)
WARNING  urllib3.connectionpool:connectionpool.py:868 Retrying (Retry(total=2, connect=None, read=None, redirect=None, status=None)) after connection broken by 'NameResolutionError("<urllib3.connection.HTTPSConnection object at 0x0000020296878E10>: Failed to resolve 'polarion-d.claas.local' ([Errno 11001] getaddrinfo failed)")': /polarion/rest/projects/Python/spaces/default/documents?page%5Bsize%5D=10&fields%5Bdocuments%5D=id%2Ctitle
DEBUG    urllib3.connectionpool:connectionpool.py:1049 Starting new HTTPS connection (14): polarion-d.claas.local:443
DEBUG    urllib3.util.retry:retry.py:521 Incremented Retry for (url='/polarion/rest/projects/Python/spaces/default/documents?page%5Bsize%5D=10&fields%5Bdocuments%5D=id%2Ctitle'): Retry(total=1, connect=None, read=None, redirect=None, status=None)
WARNING  urllib3.connectionpool:connectionpool.py:868 Retrying (Retry(total=1, connect=None, read=None, redirect=None, status=None)) after connection broken by 'NameResolutionError("<urllib3.connection.HTTPSConnection object at 0x00000202968796D0>: Failed to resolve 'polarion-d.claas.local' ([Errno 11001] getaddrinfo failed)")': /polarion/rest/projects/Python/spaces/default/documents?page%5Bsize%5D=10&fields%5Bdocuments%5D=id%2Ctitle
DEBUG    urllib3.connectionpool:connectionpool.py:1049 Starting new HTTPS connection (15): polarion-d.claas.local:443
DEBUG    urllib3.util.retry:retry.py:521 Incremented Retry for (url='/polarion/rest/projects/Python/spaces/default/documents?page%5Bsize%5D=10&fields%5Bdocuments%5D=id%2Ctitle'): Retry(total=0, connect=None, read=None, redirect=None, status=None)
WARNING  urllib3.connectionpool:connectionpool.py:868 Retrying (Retry(total=0, connect=None, read=None, redirect=None, status=None)) after connection broken by 'NameResolutionError("<urllib3.connection.HTTPSConnection object at 0x0000020296879950>: Failed to resolve 'polarion-d.claas.local' ([Errno 11001] getaddrinfo failed)")': /polarion/rest/projects/Python/spaces/default/documents?page%5Bsize%5D=10&fields%5Bdocuments%5D=id%2Ctitle
DEBUG    urllib3.connectionpool:connectionpool.py:1049 Starting new HTTPS connection (16): polarion-d.claas.local:443
DEBUG    polarion_api.documents:documents.py:555 Space 'default' not accessible: Failed to connect to https://polarion-d.claas.local/polarion/rest/projects/Python/spaces/default/documents: HTTPSConnectionPool(host='polarion-d.claas.local', port=443): Max retries exceeded with url: /polarion/rest/projects/Python/spaces/default/documents?page%5Bsize%5D=10&fields%5Bdocuments%5D=id%2Ctitle (Caused by NameResolutionError("<urllib3.connection.HTTPSConnection object at 0x0000020296879BD0>: Failed to resolve 'polarion-d.claas.local' ([Errno 11001] getaddrinfo failed)"))
DEBUG    polarion_api.client:client.py:107 GET https://polarion-d.claas.local/polarion/rest/projects/Python/spaces/Requirements/documents
DEBUG    urllib3.connectionpool:connectionpool.py:1049 Starting new HTTPS connection (17): polarion-d.claas.local:443
DEBUG    urllib3.util.retry:retry.py:521 Incremented Retry for (url='/polarion/rest/projects/Python/spaces/Requirements/documents?page%5Bsize%5D=10&fields%5Bdocuments%5D=id%2Ctitle'): Retry(total=2, connect=None, read=None, redirect=None, status=None)
WARNING  urllib3.connectionpool:connectionpool.py:868 Retrying (Retry(total=2, connect=None, read=None, redirect=None, status=None)) after connection broken by 'NameResolutionError("<urllib3.connection.HTTPSConnection object at 0x0000020296879F90>: Failed to resolve 'polarion-d.claas.local' ([Errno 11001] getaddrinfo failed)")': /polarion/rest/projects/Python/spaces/Requirements/documents?page%5Bsize%5D=10&fields%5Bdocuments%5D=id%2Ctitle
DEBUG    urllib3.connectionpool:connectionpool.py:1049 Starting new HTTPS connection (18): polarion-d.claas.local:443
DEBUG    urllib3.util.retry:retry.py:521 Incremented Retry for (url='/polarion/rest/projects/Python/spaces/Requirements/documents?page%5Bsize%5D=10&fields%5Bdocuments%5D=id%2Ctitle'): Retry(total=1, connect=None, read=None, redirect=None, status=None)
WARNING  urllib3.connectionpool:connectionpool.py:868 Retrying (Retry(total=1, connect=None, read=None, redirect=None, status=None)) after connection broken by 'NameResolutionError("<urllib3.connection.HTTPSConnection object at 0x000002029687A210>: Failed to resolve 'polarion-d.claas.local' ([Errno 11001] getaddrinfo failed)")': /polarion/rest/projects/Python/spaces/Requirements/documents?page%5Bsize%5D=10&fields%5Bdocuments%5D=id%2Ctitle
DEBUG    urllib3.connectionpool:connectionpool.py:1049 Starting new HTTPS connection (19): polarion-d.claas.local:443
DEBUG    urllib3.util.retry:retry.py:521 Incremented Retry for (url='/polarion/rest/projects/Python/spaces/Requirements/documents?page%5Bsize%5D=10&fields%5Bdocuments%5D=id%2Ctitle'): Retry(total=0, connect=None, read=None, redirect=None, status=None)
WARNING  urllib3.connectionpool:connectionpool.py:868 Retrying (Retry(total=0, connect=None, read=None, redirect=None, status=None)) after connection broken by 'NameResolutionError("<urllib3.connection.HTTPSConnection object at 0x000002029687A490>: Failed to resolve 'polarion-d.claas.local' ([Errno 11001] getaddrinfo failed)")': /polarion/rest/projects/Python/spaces/Requirements/documents?page%5Bsize%5D=10&fields%5Bdocuments%5D=id%2Ctitle
DEBUG    urllib3.connectionpool:connectionpool.py:1049 Starting new HTTPS connection (20): polarion-d.claas.local:443
DEBUG    polarion_api.documents:documents.py:555 Space 'Requirements' not accessible: Failed to connect to https://polarion-d.claas.local/polarion/rest/projects/Python/spaces/Requirements/documents: HTTPSConnectionPool(host='polarion-d.claas.local', port=443): Max retries exceeded with url: /polarion/rest/projects/Python/spaces/Requirements/documents?page%5Bsize%5D=10&fields%5Bdocuments%5D=id%2Ctitle (Caused by NameResolutionError("<urllib3.connection.HTTPSConnection object at 0x000002029687A710>: Failed to resolve 'polarion-d.claas.local' ([Errno 11001] getaddrinfo failed)"))
DEBUG    polarion_api.client:client.py:107 GET https://polarion-d.claas.local/polarion/rest/projects/Python/spaces/TestCases/documents
DEBUG    urllib3.connectionpool:connectionpool.py:1049 Starting new HTTPS connection (21): polarion-d.claas.local:443
DEBUG    urllib3.util.retry:retry.py:521 Incremented Retry for (url='/polarion/rest/projects/Python/spaces/TestCases/documents?page%5Bsize%5D=10&fields%5Bdocuments%5D=id%2Ctitle'): Retry(total=2, connect=None, read=None, redirect=None, status=None)
WARNING  urllib3.connectionpool:connectionpool.py:868 Retrying (Retry(total=2, connect=None, read=None, redirect=None, status=None)) after connection broken by 'NameResolutionError("<urllib3.connection.HTTPSConnection object at 0x000002029687AAD0>: Failed to resolve 'polarion-d.claas.local' ([Errno 11001] getaddrinfo failed)")': /polarion/rest/projects/Python/spaces/TestCases/documents?page%5Bsize%5D=10&fields%5Bdocuments%5D=id%2Ctitle
DEBUG    urllib3.connectionpool:connectionpool.py:1049 Starting new HTTPS connection (22): polarion-d.claas.local:443
DEBUG    urllib3.util.retry:retry.py:521 Incremented Retry for (url='/polarion/rest/projects/Python/spaces/TestCases/documents?page%5Bsize%5D=10&fields%5Bdocuments%5D=id%2Ctitle'): Retry(total=1, connect=None, read=None, redirect=None, status=None)
WARNING  urllib3.connectionpool:connectionpool.py:868 Retrying (Retry(total=1, connect=None, read=None, redirect=None, status=None)) after connection broken by 'NameResolutionError("<urllib3.connection.HTTPSConnection object at 0x000002029687AD50>: Failed to resolve 'polarion-d.claas.local' ([Errno 11001] getaddrinfo failed)")': /polarion/rest/projects/Python/spaces/TestCases/documents?page%5Bsize%5D=10&fields%5Bdocuments%5D=id%2Ctitle
DEBUG    urllib3.connectionpool:connectionpool.py:1049 Starting new HTTPS connection (23): polarion-d.claas.local:443
DEBUG    urllib3.util.retry:retry.py:521 Incremented Retry for (url='/polarion/rest/projects/Python/spaces/TestCases/documents?page%5Bsize%5D=10&fields%5Bdocuments%5D=id%2Ctitle'): Retry(total=0, connect=None, read=None, redirect=None, status=None)
WARNING  urllib3.connectionpool:connectionpool.py:868 Retrying (Retry(total=0, connect=None, read=None, redirect=None, status=None)) after connection broken by 'NameResolutionError("<urllib3.connection.HTTPSConnection object at 0x000002029687AFD0>: Failed to resolve 'polarion-d.claas.local' ([Errno 11001] getaddrinfo failed)")': /polarion/rest/projects/Python/spaces/TestCases/documents?page%5Bsize%5D=10&fields%5Bdocuments%5D=id%2Ctitle
DEBUG    urllib3.connectionpool:connectionpool.py:1049 Starting new HTTPS connection (24): polarion-d.claas.local:443
DEBUG    polarion_api.documents:documents.py:555 Space 'TestCases' not accessible: Failed to connect to https://polarion-d.claas.local/polarion/rest/projects/Python/spaces/TestCases/documents: HTTPSConnectionPool(host='polarion-d.claas.local', port=443): Max retries exceeded with url: /polarion/rest/projects/Python/spaces/TestCases/documents?page%5Bsize%5D=10&fields%5Bdocuments%5D=id%2Ctitle (Caused by NameResolutionError("<urllib3.connection.HTTPSConnection object at 0x000002029687B250>: Failed to resolve 'polarion-d.claas.local' ([Errno 11001] getaddrinfo failed)"))
DEBUG    polarion_api.client:client.py:107 GET https://polarion-d.claas.local/polarion/rest/projects/Python/spaces/Documents/documents
DEBUG    urllib3.connectionpool:connectionpool.py:1049 Starting new HTTPS connection (25): polarion-d.claas.local:443
DEBUG    urllib3.util.retry:retry.py:521 Incremented Retry for (url='/polarion/rest/projects/Python/spaces/Documents/documents?page%5Bsize%5D=10&fields%5Bdocuments%5D=id%2Ctitle'): Retry(total=2, connect=None, read=None, redirect=None, status=None)
WARNING  urllib3.connectionpool:connectionpool.py:868 Retrying (Retry(total=2, connect=None, read=None, redirect=None, status=None)) after connection broken by 'NameResolutionError("<urllib3.connection.HTTPSConnection object at 0x000002029687B610>: Failed to resolve 'polarion-d.claas.local' ([Errno 11001] getaddrinfo failed)")': /polarion/rest/projects/Python/spaces/Documents/documents?page%5Bsize%5D=10&fields%5Bdocuments%5D=id%2Ctitle
DEBUG    urllib3.connectionpool:connectionpool.py:1049 Starting new HTTPS connection (26): polarion-d.claas.local:443
DEBUG    urllib3.util.retry:retry.py:521 Incremented Retry for (url='/polarion/rest/projects/Python/spaces/Documents/documents?page%5Bsize%5D=10&fields%5Bdocuments%5D=id%2Ctitle'): Retry(total=1, connect=None, read=None, redirect=None, status=None)
WARNING  urllib3.connectionpool:connectionpool.py:868 Retrying (Retry(total=1, connect=None, read=None, redirect=None, status=None)) after connection broken by 'NameResolutionError("<urllib3.connection.HTTPSConnection object at 0x000002029687B890>: Failed to resolve 'polarion-d.claas.local' ([Errno 11001] getaddrinfo failed)")': /polarion/rest/projects/Python/spaces/Documents/documents?page%5Bsize%5D=10&fields%5Bdocuments%5D=id%2Ctitle
DEBUG    urllib3.connectionpool:connectionpool.py:1049 Starting new HTTPS connection (27): polarion-d.claas.local:443
DEBUG    urllib3.util.retry:retry.py:521 Incremented Retry for (url='/polarion/rest/projects/Python/spaces/Documents/documents?page%5Bsize%5D=10&fields%5Bdocuments%5D=id%2Ctitle'): Retry(total=0, connect=None, read=None, redirect=None, status=None)
WARNING  urllib3.connectionpool:connectionpool.py:868 Retrying (Retry(total=0, connect=None, read=None, redirect=None, status=None)) after connection broken by 'NameResolutionError("<urllib3.connection.HTTPSConnection object at 0x000002029687BB10>: Failed to resolve 'polarion-d.claas.local' ([Errno 11001] getaddrinfo failed)")': /polarion/rest/projects/Python/spaces/Documents/documents?page%5Bsize%5D=10&fields%5Bdocuments%5D=id%2Ctitle
DEBUG    urllib3.connectionpool:connectionpool.py:1049 Starting new HTTPS connection (28): polarion-d.claas.local:443
DEBUG    polarion_api.documents:documents.py:555 Space 'Documents' not accessible: Failed to connect to https://polarion-d.claas.local/polarion/rest/projects/Python/spaces/Documents/documents: HTTPSConnectionPool(host='polarion-d.claas.local', port=443): Max retries exceeded with url: /polarion/rest/projects/Python/spaces/Documents/documents?page%5Bsize%5D=10&fields%5Bdocuments%5D=id%2Ctitle (Caused by NameResolutionError("<urllib3.connection.HTTPSConnection object at 0x000002029687BD90>: Failed to resolve 'polarion-d.claas.local' ([Errno 11001] getaddrinfo failed)"))
DEBUG    polarion_api.client:client.py:107 GET https://polarion-d.claas.local/polarion/rest/projects/Python/spaces/Specifications/documents
DEBUG    urllib3.connectionpool:connectionpool.py:1049 Starting new HTTPS connection (29): polarion-d.claas.local:443
DEBUG    urllib3.util.retry:retry.py:521 Incremented Retry for (url='/polarion/rest/projects/Python/spaces/Specifications/documents?page%5Bsize%5D=10&fields%5Bdocuments%5D=id%2Ctitle'): Retry(total=2, connect=None, read=None, redirect=None, status=None)
WARNING  urllib3.connectionpool:connectionpool.py:868 Retrying (Retry(total=2, connect=None, read=None, redirect=None, status=None)) after connection broken by 'NameResolutionError("<urllib3.connection.HTTPSConnection object at 0x00000202968E8190>: Failed to resolve 'polarion-d.claas.local' ([Errno 11001] getaddrinfo failed)")': /polarion/rest/projects/Python/spaces/Specifications/documents?page%5Bsize%5D=10&fields%5Bdocuments%5D=id%2Ctitle
DEBUG    urllib3.connectionpool:connectionpool.py:1049 Starting new HTTPS connection (30): polarion-d.claas.local:443
DEBUG    urllib3.util.retry:retry.py:521 Incremented Retry for (url='/polarion/rest/projects/Python/spaces/Specifications/documents?page%5Bsize%5D=10&fields%5Bdocuments%5D=id%2Ctitle'): Retry(total=1, connect=None, read=None, redirect=None, status=None)
WARNING  urllib3.connectionpool:connectionpool.py:868 Retrying (Retry(total=1, connect=None, read=None, redirect=None, status=None)) after connection broken by 'NameResolutionError("<urllib3.connection.HTTPSConnection object at 0x000002029687BC50>: Failed to resolve 'polarion-d.claas.local' ([Errno 11001] getaddrinfo failed)")': /polarion/rest/projects/Python/spaces/Specifications/documents?page%5Bsize%5D=10&fields%5Bdocuments%5D=id%2Ctitle
DEBUG    urllib3.connectionpool:connectionpool.py:1049 Starting new HTTPS connection (31): polarion-d.claas.local:443
DEBUG    urllib3.util.retry:retry.py:521 Incremented Retry for (url='/polarion/rest/projects/Python/spaces/Specifications/documents?page%5Bsize%5D=10&fields%5Bdocuments%5D=id%2Ctitle'): Retry(total=0, connect=None, read=None, redirect=None, status=None)
WARNING  urllib3.connectionpool:connectionpool.py:868 Retrying (Retry(total=0, connect=None, read=None, redirect=None, status=None)) after connection broken by 'NameResolutionError("<urllib3.connection.HTTPSConnection object at 0x000002029687B110>: Failed to resolve 'polarion-d.claas.local' ([Errno 11001] getaddrinfo failed)")': /polarion/rest/projects/Python/spaces/Specifications/documents?page%5Bsize%5D=10&fields%5Bdocuments%5D=id%2Ctitle
DEBUG    urllib3.connectionpool:connectionpool.py:1049 Starting new HTTPS connection (32): polarion-d.claas.local:443
DEBUG    polarion_api.documents:documents.py:555 Space 'Specifications' not accessible: Failed to connect to https://polarion-d.claas.local/polarion/rest/projects/Python/spaces/Specifications/documents: HTTPSConnectionPool(host='polarion-d.claas.local', port=443): Max retries exceeded with url: /polarion/rest/projects/Python/spaces/Specifications/documents?page%5Bsize%5D=10&fields%5Bdocuments%5D=id%2Ctitle (Caused by NameResolutionError("<urllib3.connection.HTTPSConnection object at 0x000002029687A5D0>: Failed to resolve 'polarion-d.claas.local' ([Errno 11001] getaddrinfo failed)"))
DEBUG    polarion_api.client:client.py:107 GET https://polarion-d.claas.local/polarion/rest/projects/Python/spaces/Tests/documents
DEBUG    urllib3.connectionpool:connectionpool.py:1049 Starting new HTTPS connection (33): polarion-d.claas.local:443
DEBUG    urllib3.util.retry:retry.py:521 Incremented Retry for (url='/polarion/rest/projects/Python/spaces/Tests/documents?page%5Bsize%5D=10&fields%5Bdocuments%5D=id%2Ctitle'): Retry(total=2, connect=None, read=None, redirect=None, status=None)
WARNING  urllib3.connectionpool:connectionpool.py:868 Retrying (Retry(total=2, connect=None, read=None, redirect=None, status=None)) after connection broken by 'NameResolutionError("<urllib3.connection.HTTPSConnection object at 0x0000020296879310>: Failed to resolve 'polarion-d.claas.local' ([Errno 11001] getaddrinfo failed)")': /polarion/rest/projects/Python/spaces/Tests/documents?page%5Bsize%5D=10&fields%5Bdocuments%5D=id%2Ctitle
DEBUG    urllib3.connectionpool:connectionpool.py:1049 Starting new HTTPS connection (34): polarion-d.claas.local:443
DEBUG    urllib3.util.retry:retry.py:521 Incremented Retry for (url='/polarion/rest/projects/Python/spaces/Tests/documents?page%5Bsize%5D=10&fields%5Bdocuments%5D=id%2Ctitle'): Retry(total=1, connect=None, read=None, redirect=None, status=None)
WARNING  urllib3.connectionpool:connectionpool.py:868 Retrying (Retry(total=1, connect=None, read=None, redirect=None, status=None)) after connection broken by 'NameResolutionError("<urllib3.connection.HTTPSConnection object at 0x00000202968782D0>: Failed to resolve 'polarion-d.claas.local' ([Errno 11001] getaddrinfo failed)")': /polarion/rest/projects/Python/spaces/Tests/documents?page%5Bsize%5D=10&fields%5Bdocuments%5D=id%2Ctitle
DEBUG    urllib3.connectionpool:connectionpool.py:1049 Starting new HTTPS connection (35): polarion-d.claas.local:443
DEBUG    urllib3.util.retry:retry.py:521 Incremented Retry for (url='/polarion/rest/projects/Python/spaces/Tests/documents?page%5Bsize%5D=10&fields%5Bdocuments%5D=id%2Ctitle'): Retry(total=0, connect=None, read=None, redirect=None, status=None)
WARNING  urllib3.connectionpool:connectionpool.py:868 Retrying (Retry(total=0, connect=None, read=None, redirect=None, status=None)) after connection broken by 'NameResolutionError("<urllib3.connection.HTTPSConnection object at 0x000002029555D810>: Failed to resolve 'polarion-d.claas.local' ([Errno 11001] getaddrinfo failed)")': /polarion/rest/projects/Python/spaces/Tests/documents?page%5Bsize%5D=10&fields%5Bdocuments%5D=id%2Ctitle
DEBUG    urllib3.connectionpool:connectionpool.py:1049 Starting new HTTPS connection (36): polarion-d.claas.local:443
DEBUG    polarion_api.documents:documents.py:555 Space 'Tests' not accessible: Failed to connect to https://polarion-d.claas.local/polarion/rest/projects/Python/spaces/Tests/documents: HTTPSConnectionPool(host='polarion-d.claas.local', port=443): Max retries exceeded with url: /polarion/rest/projects/Python/spaces/Tests/documents?page%5Bsize%5D=10&fields%5Bdocuments%5D=id%2Ctitle (Caused by NameResolutionError("<urllib3.connection.HTTPSConnection object at 0x00000202968E82D0>: Failed to resolve 'polarion-d.claas.local' ([Errno 11001] getaddrinfo failed)"))
DEBUG    polarion_api.client:client.py:107 GET https://polarion-d.claas.local/polarion/rest/projects/Python/spaces/Design/documents
DEBUG    urllib3.connectionpool:connectionpool.py:1049 Starting new HTTPS connection (37): polarion-d.claas.local:443
DEBUG    urllib3.util.retry:retry.py:521 Incremented Retry for (url='/polarion/rest/projects/Python/spaces/Design/documents?page%5Bsize%5D=10&fields%5Bdocuments%5D=id%2Ctitle'): Retry(total=2, connect=None, read=None, redirect=None, status=None)
WARNING  urllib3.connectionpool:connectionpool.py:868 Retrying (Retry(total=2, connect=None, read=None, redirect=None, status=None)) after connection broken by 'NameResolutionError("<urllib3.connection.HTTPSConnection object at 0x00000202968E8690>: Failed to resolve 'polarion-d.claas.local' ([Errno 11001] getaddrinfo failed)")': /polarion/rest/projects/Python/spaces/Design/documents?page%5Bsize%5D=10&fields%5Bdocuments%5D=id%2Ctitle
DEBUG    urllib3.connectionpool:connectionpool.py:1049 Starting new HTTPS connection (38): polarion-d.claas.local:443
DEBUG    urllib3.util.retry:retry.py:521 Incremented Retry for (url='/polarion/rest/projects/Python/spaces/Design/documents?page%5Bsize%5D=10&fields%5Bdocuments%5D=id%2Ctitle'): Retry(total=1, connect=None, read=None, redirect=None, status=None)
WARNING  urllib3.connectionpool:connectionpool.py:868 Retrying (Retry(total=1, connect=None, read=None, redirect=None, status=None)) after connection broken by 'NameResolutionError("<urllib3.connection.HTTPSConnection object at 0x00000202968E8910>: Failed to resolve 'polarion-d.claas.local' ([Errno 11001] getaddrinfo failed)")': /polarion/rest/projects/Python/spaces/Design/documents?page%5Bsize%5D=10&fields%5Bdocuments%5D=id%2Ctitle
DEBUG    urllib3.connectionpool:connectionpool.py:1049 Starting new HTTPS connection (39): polarion-d.claas.local:443
DEBUG    urllib3.util.retry:retry.py:521 Incremented Retry for (url='/polarion/rest/projects/Python/spaces/Design/documents?page%5Bsize%5D=10&fields%5Bdocuments%5D=id%2Ctitle'): Retry(total=0, connect=None, read=None, redirect=None, status=None)
WARNING  urllib3.connectionpool:connectionpool.py:868 Retrying (Retry(total=0, connect=None, read=None, redirect=None, status=None)) after connection broken by 'NameResolutionError("<urllib3.connection.HTTPSConnection object at 0x00000202968E8B90>: Failed to resolve 'polarion-d.claas.local' ([Errno 11001] getaddrinfo failed)")': /polarion/rest/projects/Python/spaces/Design/documents?page%5Bsize%5D=10&fields%5Bdocuments%5D=id%2Ctitle
DEBUG    urllib3.connectionpool:connectionpool.py:1049 Starting new HTTPS connection (40): polarion-d.claas.local:443
DEBUG    polarion_api.documents:documents.py:555 Space 'Design' not accessible: Failed to connect to https://polarion-d.claas.local/polarion/rest/projects/Python/spaces/Design/documents: HTTPSConnectionPool(host='polarion-d.claas.local', port=443): Max retries exceeded with url: /polarion/rest/projects/Python/spaces/Design/documents?page%5Bsize%5D=10&fields%5Bdocuments%5D=id%2Ctitle (Caused by NameResolutionError("<urllib3.connection.HTTPSConnection object at 0x00000202968E8E10>: Failed to resolve 'polarion-d.claas.local' ([Errno 11001] getaddrinfo failed)"))
DEBUG    polarion_api.client:client.py:107 GET https://polarion-d.claas.local/polarion/rest/projects/Python/spaces/Implementation/documents
DEBUG    urllib3.connectionpool:connectionpool.py:1049 Starting new HTTPS connection (41): polarion-d.claas.local:443
DEBUG    urllib3.util.retry:retry.py:521 Incremented Retry for (url='/polarion/rest/projects/Python/spaces/Implementation/documents?page%5Bsize%5D=10&fields%5Bdocuments%5D=id%2Ctitle'): Retry(total=2, connect=None, read=None, redirect=None, status=None)
WARNING  urllib3.connectionpool:connectionpool.py:868 Retrying (Retry(total=2, connect=None, read=None, redirect=None, status=None)) after connection broken by 'NameResolutionError("<urllib3.connection.HTTPSConnection object at 0x00000202968E91D0>: Failed to resolve 'polarion-d.claas.local' ([Errno 11001] getaddrinfo failed)")': /polarion/rest/projects/Python/spaces/Implementation/documents?page%5Bsize%5D=10&fields%5Bdocuments%5D=id%2Ctitle
DEBUG    urllib3.connectionpool:connectionpool.py:1049 Starting new HTTPS connection (42): polarion-d.claas.local:443
DEBUG    urllib3.util.retry:retry.py:521 Incremented Retry for (url='/polarion/rest/projects/Python/spaces/Implementation/documents?page%5Bsize%5D=10&fields%5Bdocuments%5D=id%2Ctitle'): Retry(total=1, connect=None, read=None, redirect=None, status=None)
WARNING  urllib3.connectionpool:connectionpool.py:868 Retrying (Retry(total=1, connect=None, read=None, redirect=None, status=None)) after connection broken by 'NameResolutionError("<urllib3.connection.HTTPSConnection object at 0x00000202968E9450>: Failed to resolve 'polarion-d.claas.local' ([Errno 11001] getaddrinfo failed)")': /polarion/rest/projects/Python/spaces/Implementation/documents?page%5Bsize%5D=10&fields%5Bdocuments%5D=id%2Ctitle
DEBUG    urllib3.connectionpool:connectionpool.py:1049 Starting new HTTPS connection (43): polarion-d.claas.local:443
DEBUG    urllib3.util.retry:retry.py:521 Incremented Retry for (url='/polarion/rest/projects/Python/spaces/Implementation/documents?page%5Bsize%5D=10&fields%5Bdocuments%5D=id%2Ctitle'): Retry(total=0, connect=None, read=None, redirect=None, status=None)
WARNING  urllib3.connectionpool:connectionpool.py:868 Retrying (Retry(total=0, connect=None, read=None, redirect=None, status=None)) after connection broken by 'NameResolutionError("<urllib3.connection.HTTPSConnection object at 0x00000202968E96D0>: Failed to resolve 'polarion-d.claas.local' ([Errno 11001] getaddrinfo failed)")': /polarion/rest/projects/Python/spaces/Implementation/documents?page%5Bsize%5D=10&fields%5Bdocuments%5D=id%2Ctitle
DEBUG    urllib3.connectionpool:connectionpool.py:1049 Starting new HTTPS connection (44): polarion-d.claas.local:443
DEBUG    polarion_api.documents:documents.py:555 Space 'Implementation' not accessible: Failed to connect to https://polarion-d.claas.local/polarion/rest/projects/Python/spaces/Implementation/documents: HTTPSConnectionPool(host='polarion-d.claas.local', port=443): Max retries exceeded with url: /polarion/rest/projects/Python/spaces/Implementation/documents?page%5Bsize%5D=10&fields%5Bdocuments%5D=id%2Ctitle (Caused by NameResolutionError("<urllib3.connection.HTTPSConnection object at 0x00000202968E9950>: Failed to resolve 'polarion-d.claas.local' ([Errno 11001] getaddrinfo failed)"))
DEBUG    polarion_api.client:client.py:107 GET https://polarion-d.claas.local/polarion/rest/projects/Python/spaces/Maintenance/documents
DEBUG    urllib3.connectionpool:connectionpool.py:1049 Starting new HTTPS connection (45): polarion-d.claas.local:443
DEBUG    urllib3.util.retry:retry.py:521 Incremented Retry for (url='/polarion/rest/projects/Python/spaces/Maintenance/documents?page%5Bsize%5D=10&fields%5Bdocuments%5D=id%2Ctitle'): Retry(total=2, connect=None, read=None, redirect=None, status=None)
WARNING  urllib3.connectionpool:connectionpool.py:868 Retrying (Retry(total=2, connect=None, read=None, redirect=None, status=None)) after connection broken by 'NameResolutionError("<urllib3.connection.HTTPSConnection object at 0x00000202968E9D10>: Failed to resolve 'polarion-d.claas.local' ([Errno 11001] getaddrinfo failed)")': /polarion/rest/projects/Python/spaces/Maintenance/documents?page%5Bsize%5D=10&fields%5Bdocuments%5D=id%2Ctitle
DEBUG    urllib3.connectionpool:connectionpool.py:1049 Starting new HTTPS connection (46): polarion-d.claas.local:443
DEBUG    urllib3.util.retry:retry.py:521 Incremented Retry for (url='/polarion/rest/projects/Python/spaces/Maintenance/documents?page%5Bsize%5D=10&fields%5Bdocuments%5D=id%2Ctitle'): Retry(total=1, connect=None, read=None, redirect=None, status=None)
WARNING  urllib3.connectionpool:connectionpool.py:868 Retrying (Retry(total=1, connect=None, read=None, redirect=None, status=None)) after connection broken by 'NameResolutionError("<urllib3.connection.HTTPSConnection object at 0x00000202968E9F90>: Failed to resolve 'polarion-d.claas.local' ([Errno 11001] getaddrinfo failed)")': /polarion/rest/projects/Python/spaces/Maintenance/documents?page%5Bsize%5D=10&fields%5Bdocuments%5D=id%2Ctitle
DEBUG    urllib3.connectionpool:connectionpool.py:1049 Starting new HTTPS connection (47): polarion-d.claas.local:443
DEBUG    urllib3.util.retry:retry.py:521 Incremented Retry for (url='/polarion/rest/projects/Python/spaces/Maintenance/documents?page%5Bsize%5D=10&fields%5Bdocuments%5D=id%2Ctitle'): Retry(total=0, connect=None, read=None, redirect=None, status=None)
WARNING  urllib3.connectionpool:connectionpool.py:868 Retrying (Retry(total=0, connect=None, read=None, redirect=None, status=None)) after connection broken by 'NameResolutionError("<urllib3.connection.HTTPSConnection object at 0x00000202968EA210>: Failed to resolve 'polarion-d.claas.local' ([Errno 11001] getaddrinfo failed)")': /polarion/rest/projects/Python/spaces/Maintenance/documents?page%5Bsize%5D=10&fields%5Bdocuments%5D=id%2Ctitle
DEBUG    urllib3.connectionpool:connectionpool.py:1049 Starting new HTTPS connection (48): polarion-d.claas.local:443
DEBUG    polarion_api.documents:documents.py:555 Space 'Maintenance' not accessible: Failed to connect to https://polarion-d.claas.local/polarion/rest/projects/Python/spaces/Maintenance/documents: HTTPSConnectionPool(host='polarion-d.claas.local', port=443): Max retries exceeded with url: /polarion/rest/projects/Python/spaces/Maintenance/documents?page%5Bsize%5D=10&fields%5Bdocuments%5D=id%2Ctitle (Caused by NameResolutionError("<urllib3.connection.HTTPSConnection object at 0x00000202968EA490>: Failed to resolve 'polarion-d.claas.local' ([Errno 11001] getaddrinfo failed)"))
DEBUG    polarion_api.client:client.py:107 GET https://polarion-d.claas.local/polarion/rest/projects/Python/spaces/Product Layer/documents
DEBUG    urllib3.connectionpool:connectionpool.py:1049 Starting new HTTPS connection (49): polarion-d.claas.local:443
DEBUG    urllib3.util.retry:retry.py:521 Incremented Retry for (url='/polarion/rest/projects/Python/spaces/Product%20Layer/documents?page%5Bsize%5D=10&fields%5Bdocuments%5D=id%2Ctitle'): Retry(total=2, connect=None, read=None, redirect=None, status=None)
WARNING  urllib3.connectionpool:connectionpool.py:868 Retrying (Retry(total=2, connect=None, read=None, redirect=None, status=None)) after connection broken by 'NameResolutionError("<urllib3.connection.HTTPSConnection object at 0x00000202968EA850>: Failed to resolve 'polarion-d.claas.local' ([Errno 11001] getaddrinfo failed)")': /polarion/rest/projects/Python/spaces/Product%20Layer/documents?page%5Bsize%5D=10&fields%5Bdocuments%5D=id%2Ctitle
DEBUG    urllib3.connectionpool:connectionpool.py:1049 Starting new HTTPS connection (50): polarion-d.claas.local:443
DEBUG    urllib3.util.retry:retry.py:521 Incremented Retry for (url='/polarion/rest/projects/Python/spaces/Product%20Layer/documents?page%5Bsize%5D=10&fields%5Bdocuments%5D=id%2Ctitle'): Retry(total=1, connect=None, read=None, redirect=None, status=None)
WARNING  urllib3.connectionpool:connectionpool.py:868 Retrying (Retry(total=1, connect=None, read=None, redirect=None, status=None)) after connection broken by 'NameResolutionError("<urllib3.connection.HTTPSConnection object at 0x00000202968EAAD0>: Failed to resolve 'polarion-d.claas.local' ([Errno 11001] getaddrinfo failed)")': /polarion/rest/projects/Python/spaces/Product%20Layer/documents?page%5Bsize%5D=10&fields%5Bdocuments%5D=id%2Ctitle
DEBUG    urllib3.connectionpool:connectionpool.py:1049 Starting new HTTPS connection (51): polarion-d.claas.local:443
DEBUG    urllib3.util.retry:retry.py:521 Incremented Retry for (url='/polarion/rest/projects/Python/spaces/Product%20Layer/documents?page%5Bsize%5D=10&fields%5Bdocuments%5D=id%2Ctitle'): Retry(total=0, connect=None, read=None, redirect=None, status=None)
WARNING  urllib3.connectionpool:connectionpool.py:868 Retrying (Retry(total=0, connect=None, read=None, redirect=None, status=None)) after connection broken by 'NameResolutionError("<urllib3.connection.HTTPSConnection object at 0x00000202968EAD50>: Failed to resolve 'polarion-d.claas.local' ([Errno 11001] getaddrinfo failed)")': /polarion/rest/projects/Python/spaces/Product%20Layer/documents?page%5Bsize%5D=10&fields%5Bdocuments%5D=id%2Ctitle
DEBUG    urllib3.connectionpool:connectionpool.py:1049 Starting new HTTPS connection (52): polarion-d.claas.local:443
DEBUG    polarion_api.documents:documents.py:555 Space 'Product Layer' not accessible: Failed to connect to https://polarion-d.claas.local/polarion/rest/projects/Python/spaces/Product Layer/documents: HTTPSConnectionPool(host='polarion-d.claas.local', port=443): Max retries exceeded with url: /polarion/rest/projects/Python/spaces/Product%20Layer/documents?page%5Bsize%5D=10&fields%5Bdocuments%5D=id%2Ctitle (Caused by NameResolutionError("<urllib3.connection.HTTPSConnection object at 0x00000202968EAFD0>: Failed to resolve 'polarion-d.claas.local' ([Errno 11001] getaddrinfo failed)"))
DEBUG    polarion_api.client:client.py:107 GET https://polarion-d.claas.local/polarion/rest/projects/Python/spaces/ProductLayer/documents
DEBUG    urllib3.connectionpool:connectionpool.py:1049 Starting new HTTPS connection (53): polarion-d.claas.local:443
DEBUG    urllib3.util.retry:retry.py:521 Incremented Retry for (url='/polarion/rest/projects/Python/spaces/ProductLayer/documents?page%5Bsize%5D=10&fields%5Bdocuments%5D=id%2Ctitle'): Retry(total=2, connect=None, read=None, redirect=None, status=None)
WARNING  urllib3.connectionpool:connectionpool.py:868 Retrying (Retry(total=2, connect=None, read=None, redirect=None, status=None)) after connection broken by 'NameResolutionError("<urllib3.connection.HTTPSConnection object at 0x00000202968EB390>: Failed to resolve 'polarion-d.claas.local' ([Errno 11001] getaddrinfo failed)")': /polarion/rest/projects/Python/spaces/ProductLayer/documents?page%5Bsize%5D=10&fields%5Bdocuments%5D=id%2Ctitle
DEBUG    urllib3.connectionpool:connectionpool.py:1049 Starting new HTTPS connection (54): polarion-d.claas.local:443
DEBUG    urllib3.util.retry:retry.py:521 Incremented Retry for (url='/polarion/rest/projects/Python/spaces/ProductLayer/documents?page%5Bsize%5D=10&fields%5Bdocuments%5D=id%2Ctitle'): Retry(total=1, connect=None, read=None, redirect=None, status=None)
WARNING  urllib3.connectionpool:connectionpool.py:868 Retrying (Retry(total=1, connect=None, read=None, redirect=None, status=None)) after connection broken by 'NameResolutionError("<urllib3.connection.HTTPSConnection object at 0x00000202968EB610>: Failed to resolve 'polarion-d.claas.local' ([Errno 11001] getaddrinfo failed)")': /polarion/rest/projects/Python/spaces/ProductLayer/documents?page%5Bsize%5D=10&fields%5Bdocuments%5D=id%2Ctitle
DEBUG    urllib3.connectionpool:connectionpool.py:1049 Starting new HTTPS connection (55): polarion-d.claas.local:443
DEBUG    urllib3.util.retry:retry.py:521 Incremented Retry for (url='/polarion/rest/projects/Python/spaces/ProductLayer/documents?page%5Bsize%5D=10&fields%5Bdocuments%5D=id%2Ctitle'): Retry(total=0, connect=None, read=None, redirect=None, status=None)
WARNING  urllib3.connectionpool:connectionpool.py:868 Retrying (Retry(total=0, connect=None, read=None, redirect=None, status=None)) after connection broken by 'NameResolutionError("<urllib3.connection.HTTPSConnection object at 0x00000202968EB890>: Failed to resolve 'polarion-d.claas.local' ([Errno 11001] getaddrinfo failed)")': /polarion/rest/projects/Python/spaces/ProductLayer/documents?page%5Bsize%5D=10&fields%5Bdocuments%5D=id%2Ctitle
DEBUG    urllib3.connectionpool:connectionpool.py:1049 Starting new HTTPS connection (56): polarion-d.claas.local:443
DEBUG    polarion_api.documents:documents.py:555 Space 'ProductLayer' not accessible: Failed to connect to https://polarion-d.claas.local/polarion/rest/projects/Python/spaces/ProductLayer/documents: HTTPSConnectionPool(host='polarion-d.claas.local', port=443): Max retries exceeded with url: /polarion/rest/projects/Python/spaces/ProductLayer/documents?page%5Bsize%5D=10&fields%5Bdocuments%5D=id%2Ctitle (Caused by NameResolutionError("<urllib3.connection.HTTPSConnection object at 0x00000202968EBB10>: Failed to resolve 'polarion-d.claas.local' ([Errno 11001] getaddrinfo failed)"))
DEBUG    polarion_api.client:client.py:107 GET https://polarion-d.claas.local/polarion/rest/projects/Python/spaces/product_layer/documents
DEBUG    urllib3.connectionpool:connectionpool.py:1049 Starting new HTTPS connection (57): polarion-d.claas.local:443
DEBUG    urllib3.util.retry:retry.py:521 Incremented Retry for (url='/polarion/rest/projects/Python/spaces/product_layer/documents?page%5Bsize%5D=10&fields%5Bdocuments%5D=id%2Ctitle'): Retry(total=2, connect=None, read=None, redirect=None, status=None)
WARNING  urllib3.connectionpool:connectionpool.py:868 Retrying (Retry(total=2, connect=None, read=None, redirect=None, status=None)) after connection broken by 'NameResolutionError("<urllib3.connection.HTTPSConnection object at 0x00000202968EBED0>: Failed to resolve 'polarion-d.claas.local' ([Errno 11001] getaddrinfo failed)")': /polarion/rest/projects/Python/spaces/product_layer/documents?page%5Bsize%5D=10&fields%5Bdocuments%5D=id%2Ctitle
DEBUG    urllib3.connectionpool:connectionpool.py:1049 Starting new HTTPS connection (58): polarion-d.claas.local:443
DEBUG    urllib3.util.retry:retry.py:521 Incremented Retry for (url='/polarion/rest/projects/Python/spaces/product_layer/documents?page%5Bsize%5D=10&fields%5Bdocuments%5D=id%2Ctitle'): Retry(total=1, connect=None, read=None, redirect=None, status=None)
WARNING  urllib3.connectionpool:connectionpool.py:868 Retrying (Retry(total=1, connect=None, read=None, redirect=None, status=None)) after connection broken by 'NameResolutionError("<urllib3.connection.HTTPSConnection object at 0x0000020295670190>: Failed to resolve 'polarion-d.claas.local' ([Errno 11001] getaddrinfo failed)")': /polarion/rest/projects/Python/spaces/product_layer/documents?page%5Bsize%5D=10&fields%5Bdocuments%5D=id%2Ctitle
DEBUG    urllib3.connectionpool:connectionpool.py:1049 Starting new HTTPS connection (59): polarion-d.claas.local:443
DEBUG    urllib3.util.retry:retry.py:521 Incremented Retry for (url='/polarion/rest/projects/Python/spaces/product_layer/documents?page%5Bsize%5D=10&fields%5Bdocuments%5D=id%2Ctitle'): Retry(total=0, connect=None, read=None, redirect=None, status=None)
WARNING  urllib3.connectionpool:connectionpool.py:868 Retrying (Retry(total=0, connect=None, read=None, redirect=None, status=None)) after connection broken by 'NameResolutionError("<urllib3.connection.HTTPSConnection object at 0x0000020295670410>: Failed to resolve 'polarion-d.claas.local' ([Errno 11001] getaddrinfo failed)")': /polarion/rest/projects/Python/spaces/product_layer/documents?page%5Bsize%5D=10&fields%5Bdocuments%5D=id%2Ctitle
DEBUG    urllib3.connectionpool:connectionpool.py:1049 Starting new HTTPS connection (60): polarion-d.claas.local:443
DEBUG    polarion_api.documents:documents.py:555 Space 'product_layer' not accessible: Failed to connect to https://polarion-d.claas.local/polarion/rest/projects/Python/spaces/product_layer/documents: HTTPSConnectionPool(host='polarion-d.claas.local', port=443): Max retries exceeded with url: /polarion/rest/projects/Python/spaces/product_layer/documents?page%5Bsize%5D=10&fields%5Bdocuments%5D=id%2Ctitle (Caused by NameResolutionError("<urllib3.connection.HTTPSConnection object at 0x0000020295670690>: Failed to resolve 'polarion-d.claas.local' ([Errno 11001] getaddrinfo failed)"))
DEBUG    polarion_api.client:client.py:107 GET https://polarion-d.claas.local/polarion/rest/projects/Python/spaces/Product-Layer/documents
DEBUG    urllib3.connectionpool:connectionpool.py:1049 Starting new HTTPS connection (61): polarion-d.claas.local:443
DEBUG    urllib3.util.retry:retry.py:521 Incremented Retry for (url='/polarion/rest/projects/Python/spaces/Product-Layer/documents?page%5Bsize%5D=10&fields%5Bdocuments%5D=id%2Ctitle'): Retry(total=2, connect=None, read=None, redirect=None, status=None)
WARNING  urllib3.connectionpool:connectionpool.py:868 Retrying (Retry(total=2, connect=None, read=None, redirect=None, status=None)) after connection broken by 'NameResolutionError("<urllib3.connection.HTTPSConnection object at 0x0000020295670A50>: Failed to resolve 'polarion-d.claas.local' ([Errno 11001] getaddrinfo failed)")': /polarion/rest/projects/Python/spaces/Product-Layer/documents?page%5Bsize%5D=10&fields%5Bdocuments%5D=id%2Ctitle
DEBUG    urllib3.connectionpool:connectionpool.py:1049 Starting new HTTPS connection (62): polarion-d.claas.local:443
DEBUG    urllib3.util.retry:retry.py:521 Incremented Retry for (url='/polarion/rest/projects/Python/spaces/Product-Layer/documents?page%5Bsize%5D=10&fields%5Bdocuments%5D=id%2Ctitle'): Retry(total=1, connect=None, read=None, redirect=None, status=None)
WARNING  urllib3.connectionpool:connectionpool.py:868 Retrying (Retry(total=1, connect=None, read=None, redirect=None, status=None)) after connection broken by 'NameResolutionError("<urllib3.connection.HTTPSConnection object at 0x0000020295670CD0>: Failed to resolve 'polarion-d.claas.local' ([Errno 11001] getaddrinfo failed)")': /polarion/rest/projects/Python/spaces/Product-Layer/documents?page%5Bsize%5D=10&fields%5Bdocuments%5D=id%2Ctitle
DEBUG    urllib3.connectionpool:connectionpool.py:1049 Starting new HTTPS connection (63): polarion-d.claas.local:443
DEBUG    urllib3.util.retry:retry.py:521 Incremented Retry for (url='/polarion/rest/projects/Python/spaces/Product-Layer/documents?page%5Bsize%5D=10&fields%5Bdocuments%5D=id%2Ctitle'): Retry(total=0, connect=None, read=None, redirect=None, status=None)
WARNING  urllib3.connectionpool:connectionpool.py:868 Retrying (Retry(total=0, connect=None, read=None, redirect=None, status=None)) after connection broken by 'NameResolutionError("<urllib3.connection.HTTPSConnection object at 0x0000020295670F50>: Failed to resolve 'polarion-d.claas.local' ([Errno 11001] getaddrinfo failed)")': /polarion/rest/projects/Python/spaces/Product-Layer/documents?page%5Bsize%5D=10&fields%5Bdocuments%5D=id%2Ctitle
DEBUG    urllib3.connectionpool:connectionpool.py:1049 Starting new HTTPS connection (64): polarion-d.claas.local:443
DEBUG    polarion_api.documents:documents.py:555 Space 'Product-Layer' not accessible: Failed to connect to https://polarion-d.claas.local/polarion/rest/projects/Python/spaces/Product-Layer/documents: HTTPSConnectionPool(host='polarion-d.claas.local', port=443): Max retries exceeded with url: /polarion/rest/projects/Python/spaces/Product-Layer/documents?page%5Bsize%5D=10&fields%5Bdocuments%5D=id%2Ctitle (Caused by NameResolutionError("<urllib3.connection.HTTPSConnection object at 0x00000202956711D0>: Failed to resolve 'polarion-d.claas.local' ([Errno 11001] getaddrinfo failed)"))
DEBUG    polarion_api.client:client.py:107 GET https://polarion-d.claas.local/polarion/rest/projects/Python/spaces/product-layer/documents
DEBUG    urllib3.connectionpool:connectionpool.py:1049 Starting new HTTPS connection (65): polarion-d.claas.local:443
DEBUG    urllib3.util.retry:retry.py:521 Incremented Retry for (url='/polarion/rest/projects/Python/spaces/product-layer/documents?page%5Bsize%5D=10&fields%5Bdocuments%5D=id%2Ctitle'): Retry(total=2, connect=None, read=None, redirect=None, status=None)
WARNING  urllib3.connectionpool:connectionpool.py:868 Retrying (Retry(total=2, connect=None, read=None, redirect=None, status=None)) after connection broken by 'NameResolutionError("<urllib3.connection.HTTPSConnection object at 0x0000020295671590>: Failed to resolve 'polarion-d.claas.local' ([Errno 11001] getaddrinfo failed)")': /polarion/rest/projects/Python/spaces/product-layer/documents?page%5Bsize%5D=10&fields%5Bdocuments%5D=id%2Ctitle
DEBUG    urllib3.connectionpool:connectionpool.py:1049 Starting new HTTPS connection (66): polarion-d.claas.local:443
DEBUG    urllib3.util.retry:retry.py:521 Incremented Retry for (url='/polarion/rest/projects/Python/spaces/product-layer/documents?page%5Bsize%5D=10&fields%5Bdocuments%5D=id%2Ctitle'): Retry(total=1, connect=None, read=None, redirect=None, status=None)
WARNING  urllib3.connectionpool:connectionpool.py:868 Retrying (Retry(total=1, connect=None, read=None, redirect=None, status=None)) after connection broken by 'NameResolutionError("<urllib3.connection.HTTPSConnection object at 0x0000020295671810>: Failed to resolve 'polarion-d.claas.local' ([Errno 11001] getaddrinfo failed)")': /polarion/rest/projects/Python/spaces/product-layer/documents?page%5Bsize%5D=10&fields%5Bdocuments%5D=id%2Ctitle
DEBUG    urllib3.connectionpool:connectionpool.py:1049 Starting new HTTPS connection (67): polarion-d.claas.local:443
DEBUG    urllib3.util.retry:retry.py:521 Incremented Retry for (url='/polarion/rest/projects/Python/spaces/product-layer/documents?page%5Bsize%5D=10&fields%5Bdocuments%5D=id%2Ctitle'): Retry(total=0, connect=None, read=None, redirect=None, status=None)
WARNING  urllib3.connectionpool:connectionpool.py:868 Retrying (Retry(total=0, connect=None, read=None, redirect=None, status=None)) after connection broken by 'NameResolutionError("<urllib3.connection.HTTPSConnection object at 0x00000202968EB9D0>: Failed to resolve 'polarion-d.claas.local' ([Errno 11001] getaddrinfo failed)")': /polarion/rest/projects/Python/spaces/product-layer/documents?page%5Bsize%5D=10&fields%5Bdocuments%5D=id%2Ctitle
DEBUG    urllib3.connectionpool:connectionpool.py:1049 Starting new HTTPS connection (68): polarion-d.claas.local:443
DEBUG    polarion_api.documents:documents.py:555 Space 'product-layer' not accessible: Failed to connect to https://polarion-d.claas.local/polarion/rest/projects/Python/spaces/product-layer/documents: HTTPSConnectionPool(host='polarion-d.claas.local', port=443): Max retries exceeded with url: /polarion/rest/projects/Python/spaces/product-layer/documents?page%5Bsize%5D=10&fields%5Bdocuments%5D=id%2Ctitle (Caused by NameResolutionError("<urllib3.connection.HTTPSConnection object at 0x00000202968EAE90>: Failed to resolve 'polarion-d.claas.local' ([Errno 11001] getaddrinfo failed)"))
INFO     polarion_api.documents:documents.py:502 Discovery completed: Found 0 spaces and 0 documents
2025-08-06 09:07:13,895 [INFO] [__main__] Test reports saved to: test_reports\20250806_090527
2025-08-06 09:07:13,896 [INFO] [__main__] Logs saved to: test_reports\20250806_090527/logs/pytest.log
