DEBUG    tests.moduletest.conftest:conftest.py:25 Loaded .env from C:\Users\E017093\gitRepos\PolarionMock\.env
INFO     tests.session:conftest.py:231 ================================================================================
INFO     tests.session:conftest.py:232 Test Session Started: 20250806_111558
INFO     tests.session:conftest.py:233 Environment: production
INFO     tests.session:conftest.py:234 ================================================================================
DEBUG    tests.session:conftest.py:151 Test environment: production
DEBUG    tests.session:conftest.py:152 Base URL: N/A
INFO     tests.moduletest.test_document_discovery:test_document_discovery.py:38 Testing against: production
INFO     src.polarion_api.client:client.py:60 Initialized Polarion client for https://polarion-d.claas.local
INFO     tests.moduletest.test_document_discovery:test_document_discovery.py:22 Using project ID: Python
INFO     tests.moduletest.test_document_discovery:test_document_discovery.py:87 Testing document discovery for project: Python
INFO     src.polarion_api.documents:documents.py:851 Starting comprehensive document and space discovery for project: Python
INFO     src.polarion_api.documents:documents.py:867 Fetching work items page 1
DEBUG    src.polarion_api.client:client.py:107 GET https://polarion-d.claas.local/polarion/rest/projects/Python/workitems
DEBUG    urllib3.connectionpool:connectionpool.py:1049 Starting new HTTPS connection (1): polarion-d.claas.local:443
DEBUG    urllib3.connectionpool:connectionpool.py:544 https://polarion-d.claas.local:443 "GET /polarion/rest/projects/Python/workitems?page%5Bsize%5D=100&page%5Bnumber%5D=1&fields%5Bworkitems%5D=%40all&fields%5Bdocuments%5D=%40all HTTP/1.1" 404 139
DEBUG    src.polarion_api.client:client.py:115 Response status: 404
DEBUG    src.polarion_api.client:client.py:117 Response body: {"errors":[{"status":"404","title":"Not Found","detail":"The requested resource [/polarion/rest/projects/Python/workitems] is not available"}]}...
ERROR    src.polarion_api.documents:documents.py:892 Error fetching work items: Unexpected error: [404] Python with ID 'workitems?page%5Bsize%5D=100&page%5Bnumber%5D=1&fields%5Bworkitems%5D=%40all&fields%5Bdocuments%5D=%40all' not found
INFO     src.polarion_api.documents:documents.py:895 Fetched 0 work items across 0 pages
INFO     src.polarion_api.documents:documents.py:910 Saved raw work items to tests/moduletest/outputdata\workitems_response.json
INFO     src.polarion_api.documents:documents.py:983 Saved discovered documents to tests/moduletest/outputdata\discovered_documents.json
INFO     src.polarion_api.documents:documents.py:986 Discovery complete:
INFO     src.polarion_api.documents:documents.py:987   - Spaces found: 0
INFO     src.polarion_api.documents:documents.py:991   - Documents found: 0
INFO     src.polarion_api.documents:documents.py:992   - Work items with modules: 0
INFO     src.polarion_api.documents:documents.py:993   - Work items without modules: 0
INFO     tests.moduletest.test_document_discovery:test_document_discovery.py:142 Statistics:
INFO     tests.moduletest.test_document_discovery:test_document_discovery.py:143   - Total spaces: 0
INFO     tests.moduletest.test_document_discovery:test_document_discovery.py:144   - Total documents: 0
INFO     tests.moduletest.test_document_discovery:test_document_discovery.py:145   - Work items processed: 0
INFO     tests.moduletest.test_document_discovery:test_document_discovery.py:146   - Work items with modules: 0
INFO     tests.moduletest.test_document_discovery:test_document_discovery.py:147   - Work items without modules: 0
INFO     tests.moduletest.test_document_discovery:test_document_discovery.py:74 Saved response to tests/moduletest/outputdata\discovered_documents_20250806_111559.json
INFO     tests.moduletest.test_document_discovery:test_document_discovery.py:74 Saved response to tests/moduletest/outputdata\discovered_documents.json
2025-08-06 11:15:59,232 [INFO] [__main__] Test reports saved to: test_reports\20250806_111557
2025-08-06 11:15:59,232 [INFO] [__main__] Logs saved to: test_reports\20250806_111557/logs/pytest.log
